    <model name="costar_husky_sensor_config_1">
      <link name="base_link">
        <pose frame="">0 1 0 0 -0 0</pose>
        <inertial>
          <pose frame="">0 0 0.062329 0 -0 0</pose>
          <mass>46.064</mass>
          <inertia>
            <ixx>0.615397</ixx>
            <ixy>-0.0240585</ixy>
            <ixz>-0.120749</ixz>
            <iyy>1.75388</iyy>
            <iyz>-0.0028322</iyz>
            <izz>2.03641</izz>
          </inertia>
        </inertial>
        <collision name="base_link_collision">
          <pose frame="">0 0 0.12 0 0 0</pose>
          <geometry>
            <box>
              <size>0.9874 0.5709 0.05</size>
            </box>
          </geometry>
        </collision>
        <collision name="base_link_collision_bottom">
          <pose frame="">0 0 0.046 0 0 0</pose>
          <geometry>
            <box>
              <size>0.80 0.5709 0.095</size>
            </box>
          </geometry>
        </collision>
        <collision name="base_link_collision_1">
          <pose frame="">0 0 0.185625 0 -0 0</pose>
          <geometry>
            <box>
              <size>0.78992 0.5709 0.12375</size>
            </box>
          </geometry>
        </collision>
        <collision name="base_link_fixed_joint_lump__camera/camera_link_collision_2">
          <pose frame="">0.488 0 0.272 0 -0 0</pose>
          <geometry>
            <box>
              <size>0.0078 0.13 0.0192</size>
            </box>
          </geometry>
          <surface>
            <contact>
              <ode>
                <kp>1e+13</kp>
                <kd>1</kd>
              </ode>
            </contact>
            <friction>
              <ode>
                <mu2>1</mu2>
                <fdir1>0 0 0</fdir1>
              </ode>
            </friction>
          </surface>
        </collision>
        <collision name="base_link_fixed_joint_lump__top_plate_link_collision_3">
          <pose frame="">0.0812 0 0.245 0 -0 0</pose>
          <geometry>
            <mesh>
              <scale>1 1 1</scale>
              <uri>meshes/top_plate.dae</uri>
            </mesh>
          </geometry>
        </collision>
        <collision name="base_link_fixed_joint_lump__top_plate_link_collision_4">
          <pose frame="">0.0812 0 0.245 0 -0 0</pose>
          <geometry>
            <box>
              <size>0.32 0.41 0.09</size>
            </box>
          </geometry>
        </collision>
        <collision name="base_link_fixed_joint_lump__velodyne_base_link_collision_5">
          <pose frame="">0.0012 0 0.71415 0 -0 0</pose>
          <geometry>
            <cylinder>
              <length>0.0717</length>
              <radius>0.0516</radius>
            </cylinder>
          </geometry>
        </collision>
        <visual name="base_link_visual">
          <pose frame="">0 0 0 0 -0 0</pose>
          <geometry>
            <mesh>
              <scale>1 1 1</scale>
              <uri>meshes/base_link.dae</uri>
            </mesh>
          </geometry>
        </visual>
        <visual name="base_link_fixed_joint_lump__camera/camera_link_visual_1">
          <pose frame="">0.438 0 0.272 0 -0 0</pose>
          <geometry>
            <mesh>
              <uri>meshes/realsense.dae</uri>
            </mesh>
          </geometry>
        </visual>
        <visual name="base_link_fixed_joint_lump__cliff_sensor_link_visual_2">
          <pose frame="">0.435 0 0.235 -2.35619 -0 -1.5708</pose>
          <geometry>
            <cylinder>
              <length>0.02</length>
              <radius>0.005</radius>
            </cylinder>
          </geometry>
        </visual>
        <visual name="base_link_fixed_joint_lump__front_bumper_link_visual_3">
          <pose frame="">0.48 0 0.091 0 -0 0</pose>
          <geometry>
            <mesh>
              <scale>1 1 1</scale>
              <uri>meshes/bumper.dae</uri>
            </mesh>
          </geometry>
        </visual>
        <visual name="base_link_fixed_joint_lump__rear_bumper_link_visual_4">
          <pose frame="">-0.48 0 0.091 0 -0 3.14159</pose>
          <geometry>
            <mesh>
              <scale>1 1 1</scale>
              <uri>meshes/bumper.dae</uri>
            </mesh>
          </geometry>
        </visual>
        <visual name="base_link_fixed_joint_lump__top_chassis_link_visual_5">
          <pose frame="">0 0 0 0 -0 0</pose>
          <geometry>
            <mesh>
              <scale>1 1 1</scale>
              <uri>meshes/top_chassis.dae</uri>
            </mesh>
          </geometry>
        </visual>
        <visual name="base_link_fixed_joint_lump__top_plate_link_visual_6">
          <pose frame="">0.0812 0 0.245 0 -0 0</pose>
          <geometry>
            <mesh>
              <scale>1 1 1</scale>
              <uri>meshes/top_plate.dae</uri>
            </mesh>
          </geometry>
        </visual>
        <visual name="base_link_fixed_joint_lump__arch_visual_7">
          <pose frame="">0.0012 0 0.251 0 -0 0</pose>
          <geometry>
            <mesh>
              <scale>1 1 1</scale>
              <uri>meshes/jpl04_arch_nosensor.stl</uri>
            </mesh>
          </geometry>
          <material>
            <ambient>0.8 0.8 0.8 1</ambient>
            <diffuse>0.45 0.45 0.45 1</diffuse>
            <specular>0.8 0.8 0.8 1.0</specular>
          </material>
        </visual>
        <visual name="base_link_fixed_joint_lump__velodyne_base_link_visual_10">
          <pose frame="">0.0012 0 0.6783 0 -0 0</pose>
          <geometry>
            <mesh>
              <scale>1 1 1</scale>
              <uri>meshes/VLP16_base_1.dae</uri>
            </mesh>
          </geometry>
        </visual>
        <visual name="base_link_fixed_joint_lump__velodyne_base_link_visual_11">
          <pose frame="">0.0012 0 0.6783 0 -0 0</pose>
          <geometry>
            <mesh>
              <scale>1 1 1</scale>
              <uri>meshes/VLP16_base_2.dae</uri>
            </mesh>
          </geometry>
        </visual>
        <visual name="base_link_fixed_joint_lump__velodyne_visual_12">
          <pose frame="">0.0012 0 0.6783 0 -0 0</pose>
          <geometry>
            <mesh>
              <scale>1 1 1</scale>
              <uri>meshes/VLP16_scan.dae</uri>
            </mesh>
          </geometry>
        </visual>
        <visual name="base_link_fixed_joint_lump__user_rail_link_visual_13">
          <pose frame="">0.272 0 0.245 0 -0 0</pose>
          <geometry>
            <mesh>
              <scale>1 1 1</scale>
              <uri>meshes/user_rail.dae</uri>
            </mesh>
          </geometry>
        </visual>
        <velocity_decay/>
        <self_collide>0</self_collide>
        <enable_wind>0</enable_wind>
        <kinematic>0</kinematic>

        <!-- DiffDrive Plugin -->
        <plugin name='ignition::gazebo::systems::DiffDrive' filename='ignition-gazebo-diff-drive-system'>
          <left_joint>rear_left_wheel_joint</left_joint>
          <right_joint>rear_right_wheel_joint</right_joint>
          <wheel_separation>0.5709</wheel_separation>
          <wheel_radius>0.1651</wheel_radius>
          <odom_publish_frequency>20</odom_publish_frequency>
          <frame_id>odom</frame_id>
          <child_frame_id>base_link</child_frame_id>
        </plugin>

        <!-- Joint Controllers -->
        <plugin name='ignition::gazebo::systems::JointController' filename='ignition-gazebo-joint-controller-system'>
          <joint_name>front_left_wheel_joint</joint_name>
          <use_force_commands>true</use_force_commands>
          <p_gain>0.2</p_gain>
          <i_gain>0.01</i_gain>
        </plugin>
        <plugin name='ignition::gazebo::systems::JointController' filename='ignition-gazebo-joint-controller-system'>
          <joint_name>front_right_wheel_joint</joint_name>
          <use_force_commands>true</use_force_commands>
          <p_gain>0.2</p_gain>
          <i_gain>0.01</i_gain>
        </plugin>

        <!-- Pose Publisher Plugin -->
        <plugin name='ignition::gazebo::systems::PosePublisher' filename='ignition-gazebo-pose-publisher-system'>
          <publish_link_pose>true</publish_link_pose>
          <publish_collision_pose>false</publish_collision_pose>
          <publish_visual_pose>false</publish_visual_pose>
          <publish_sensor_pose>false</publish_sensor_pose>
          <publish_nested_model_pose>true</publish_nested_model_pose>
          <update_frequency>20</update_frequency>
        </plugin>

        <!-- Battery Plugin -->
        <plugin name='ignition::gazebo::systems::LinearBatteryPlugin' filename='ignition-gazebo-linearbatteryplugin-system'>
          <battery_name>linear_battery</battery_name>
          <voltage>24.592</voltage>
          <open_circuit_voltage_constant_coef>24.592</open_circuit_voltage_constant_coef>
          <capacity>1.2009</capacity>
          <power_load>6.5</power_load>
          <fix_issue_225>true</fix_issue_225>
          <enable_recharge>true</enable_recharge>
          <charging_time>3.0</charging_time>
          <recharge_by_topic>true</recharge_by_topic>
        </plugin>

        <!-- IMU Sensor -->
        <sensor name="imu_sensor" type="imu">
          <always_on>1</always_on>
          <update_rate>50</update_rate>
          <imu>
            <enable_orientation>0</enable_orientation>
            <angular_velocity>
              <x>
                <noise type="gaussian">
                  <mean>0</mean>
                  <stddev>0.009</stddev>
                  <bias_mean>0.00075</bias_mean>
                  <bias_stddev>0.005</bias_stddev>
                  <dynamic_bias_stddev>0.00002</dynamic_bias_stddev>
                  <dynamic_bias_correlation_time>400.0</dynamic_bias_correlation_time>
                  <precision>0.00025</precision>
                </noise>
              </x>
              <y>
                <noise type="gaussian">
                  <mean>0</mean>
                  <stddev>0.009</stddev>
                  <bias_mean>0.00075</bias_mean>
                  <bias_stddev>0.005</bias_stddev>
                  <dynamic_bias_stddev>0.00002</dynamic_bias_stddev>
                  <dynamic_bias_correlation_time>400.0</dynamic_bias_correlation_time>
                  <precision>0.00025</precision>
                </noise>
              </y>
              <z>
                <noise type="gaussian">
                  <mean>0</mean>
                  <stddev>0.009</stddev>
                  <bias_mean>0.00075</bias_mean>
                  <bias_stddev>0.005</bias_stddev>
                  <dynamic_bias_stddev>0.00002</dynamic_bias_stddev>
                  <dynamic_bias_correlation_time>400.0</dynamic_bias_correlation_time>
                  <precision>0.00025</precision>
                </noise>
              </z>
            </angular_velocity>
            <linear_acceleration>
              <x>
                <noise type="gaussian">
                  <mean>0</mean>
                  <stddev>0.021</stddev>
                  <bias_mean>0.05</bias_mean>
                  <bias_stddev>0.0075</bias_stddev>
                  <dynamic_bias_stddev>0.000375</dynamic_bias_stddev>
                  <dynamic_bias_correlation_time>175.0</dynamic_bias_correlation_time>
                  <precision>0.005</precision>
                </noise>
              </x>
              <y>
                <noise type="gaussian">
                  <mean>0</mean>
                  <stddev>0.021</stddev>
                  <bias_mean>0.05</bias_mean>
                  <bias_stddev>0.0075</bias_stddev>
                  <dynamic_bias_stddev>0.000375</dynamic_bias_stddev>
                  <dynamic_bias_correlation_time>175.0</dynamic_bias_correlation_time>
                  <precision>0.005</precision>
                </noise>
              </y>
              <z>
                <noise type="gaussian">
                  <mean>0</mean>
                  <stddev>0.021</stddev>
                  <bias_mean>0.05</bias_mean>
                  <bias_stddev>0.0075</bias_stddev>
                  <dynamic_bias_stddev>0.000375</dynamic_bias_stddev>
                  <dynamic_bias_correlation_time>175.0</dynamic_bias_correlation_time>
                  <precision>0.005</precision>
                </noise>
              </z>
            </linear_acceleration>
          </imu>
        </sensor>
      </link>

      <link name="front_left_wheel_link">
        <pose frame="">0.256 1.2854 0.03282 0 -0 0</pose>
        <inertial>
          <pose frame="">0 0 0 0 -0 0</pose>
          <mass>2.637</mass>
          <inertia>
            <ixx>0.02467</ixx>
            <ixy>0</ixy>
            <ixz>0</ixz>
            <iyy>0.04411</iyy>
            <iyz>0</iyz>
            <izz>0.02467</izz>
          </inertia>
        </inertial>
        <collision name="front_left_wheel_link_collision">
          <pose frame="">0 0 0 1.5707963267948966 -0 0</pose>
          <geometry>
            <cylinder>
              <length>0.1143</length>
              <radius>0.1651</radius>
            </cylinder>
          </geometry>
          <surface>
            <contact>
              <ode>
                <kp>1e+07</kp>
                <kd>1</kd>
              </ode>
            </contact>
            <friction>
              <ode>
                <mu>0.5</mu>
                <mu2>1</mu2>
                <slip1>0.00062</slip1>
                <slip2>0</slip2>
                <fdir1>0 0 1</fdir1>
              </ode>
            </friction>
          </surface>
        </collision>
        <visual name="front_left_wheel_link_visual">
          <pose frame="">0 0 0 0 -0 0</pose>
          <geometry>
            <mesh>
              <scale>1 1 1</scale>
              <uri>meshes/wheel.dae</uri>
            </mesh>
          </geometry>
        </visual>
        <gravity>1</gravity>
        <velocity_decay/>
      </link>
      <joint name="front_left_wheel_joint" type="revolute">
        <child>front_left_wheel_link</child>
        <parent>base_link</parent>
        <axis>
          <xyz>0 1 0</xyz>
          <limit>
            <lower>-1e+16</lower>
            <upper>1e+16</upper>
          </limit>
          <dynamics>
            <spring_reference>0</spring_reference>
            <spring_stiffness>0</spring_stiffness>
          </dynamics>
          <use_parent_model_frame>1</use_parent_model_frame>
        </axis>
      </joint>
      <link name="front_right_wheel_link">
        <pose frame="">0.256 0.7145 0.03282 0 -0 0</pose>
        <inertial>
          <pose frame="">0 0 0 0 -0 0</pose>
          <mass>2.637</mass>
          <inertia>
            <ixx>0.02467</ixx>
            <ixy>0</ixy>
            <ixz>0</ixz>
            <iyy>0.04411</iyy>
            <iyz>0</iyz>
            <izz>0.02467</izz>
          </inertia>
        </inertial>
        <collision name="front_right_wheel_link_collision">
          <pose frame="">0 0 0 1.5707963267948966 -0 0</pose>
          <geometry>
            <cylinder>
              <length>0.1143</length>
              <radius>0.1651</radius>
            </cylinder>
          </geometry>
          <surface>
            <contact>
              <ode>
                <kp>1e+07</kp>
                <kd>1</kd>
              </ode>
            </contact>
            <friction>
              <ode>
                <mu>0.5</mu>
                <mu2>1</mu2>
                <slip1>0.00062</slip1>
                <slip2>0</slip2>
                <fdir1>0 0 1</fdir1>
              </ode>
            </friction>
          </surface>
        </collision>
        <visual name="front_right_wheel_link_visual">
          <pose frame="">0 0 0 0 -0 0</pose>
          <geometry>
            <mesh>
              <scale>1 1 1</scale>
              <uri>meshes/wheel.dae</uri>
            </mesh>
          </geometry>
        </visual>
        <gravity>1</gravity>
        <velocity_decay/>
      </link>
      <joint name="front_right_wheel_joint" type="revolute">
        <child>front_right_wheel_link</child>
        <parent>base_link</parent>
        <axis>
          <xyz>0 1 0</xyz>
          <limit>
            <lower>-1e+16</lower>
            <upper>1e+16</upper>
          </limit>
          <dynamics>
            <spring_reference>0</spring_reference>
            <spring_stiffness>0</spring_stiffness>
          </dynamics>
          <use_parent_model_frame>1</use_parent_model_frame>
        </axis>
      </joint>
      <link name="rear_left_wheel_link">
        <pose frame="">-0.256 1.2854 0.03282 0 -0 0</pose>
        <inertial>
          <pose frame="">0 0 0 0 -0 0</pose>
          <mass>2.637</mass>
          <inertia>
            <ixx>0.02467</ixx>
            <ixy>0</ixy>
            <ixz>0</ixz>
            <iyy>0.04411</iyy>
            <iyz>0</iyz>
            <izz>0.02467</izz>
          </inertia>
        </inertial>
        <collision name="rear_left_wheel_link_collision">
          <pose frame="">0 0 0 1.5707963267948966 -0 0</pose>
          <geometry>
            <cylinder>
              <length>0.1143</length>
              <radius>0.1651</radius>
            </cylinder>
          </geometry>
          <surface>
            <contact>
              <ode>
                <kp>1e+07</kp>
                <kd>1</kd>
              </ode>
            </contact>
            <friction>
              <ode>
                <mu>0.5</mu>
                <mu2>1</mu2>
                <slip1>0.00062</slip1>
                <slip2>0</slip2>
                <fdir1>0 0 1</fdir1>
              </ode>
            </friction>
          </surface>
        </collision>
        <visual name="rear_left_wheel_link_visual">
          <pose frame="">0 0 0 0 -0 0</pose>
          <geometry>
            <mesh>
              <scale>1 1 1</scale>
              <uri>meshes/wheel.dae</uri>
            </mesh>
          </geometry>
        </visual>
        <gravity>1</gravity>
        <velocity_decay/>
      </link>
      <joint name="rear_left_wheel_joint" type="revolute">
        <child>rear_left_wheel_link</child>
        <parent>base_link</parent>
        <axis>
          <xyz>0 1 0</xyz>
          <limit>
            <lower>-1e+16</lower>
            <upper>1e+16</upper>
          </limit>
          <dynamics>
            <spring_reference>0</spring_reference>
            <spring_stiffness>0</spring_stiffness>
          </dynamics>
          <use_parent_model_frame>1</use_parent_model_frame>
        </axis>
      </joint>
      <link name="rear_right_wheel_link">
        <pose frame="">-0.256 0.7145 0.03282 0 -0 0</pose>
        <inertial>
          <pose frame="">0 0 0 0 -0 0</pose>
          <mass>2.637</mass>
          <inertia>
            <ixx>0.02467</ixx>
            <ixy>0</ixy>
            <ixz>0</ixz>
            <iyy>0.04411</iyy>
            <iyz>0</iyz>
            <izz>0.02467</izz>
          </inertia>
        </inertial>
        <collision name="rear_right_wheel_link_collision">
          <pose frame="">0 0 0 1.5707963267948966 -0 0</pose>
          <geometry>
            <cylinder>
              <length>0.1143</length>
              <radius>0.1651</radius>
            </cylinder>
          </geometry>
          <surface>
            <contact>
              <ode>
                <kp>1e+07</kp>
                <kd>1</kd>
              </ode>
            </contact>
            <friction>
              <ode>
                <mu>0.5</mu>
                <mu2>1</mu2>
                <slip1>0.00062</slip1>
                <slip2>0</slip2>
                <fdir1>0 0 1</fdir1>
              </ode>
            </friction>
          </surface>
        </collision>
        <visual name="rear_right_wheel_link_visual">
          <pose frame="">0 0 0 0 -0 0</pose>
          <geometry>
            <mesh>
              <scale>1 1 1</scale>
              <uri>meshes/wheel.dae</uri>
            </mesh>
          </geometry>
        </visual>
        <gravity>1</gravity>
        <velocity_decay/>
      </link>
      <joint name="rear_right_wheel_joint" type="revolute">
        <child>rear_right_wheel_link</child>
        <parent>base_link</parent>
        <axis>
          <xyz>0 1 0</xyz>
          <limit>
            <lower>-1e+16</lower>
            <upper>1e+16</upper>
          </limit>
          <dynamics>
            <spring_reference>0</spring_reference>
            <spring_stiffness>0</spring_stiffness>
          </dynamics>
          <use_parent_model_frame>1</use_parent_model_frame>
        </axis>
      </joint>
      <static>0</static>
    </model>